Workbook

Sheet Supuestos
A1: Supuestos de costeo del proyecto
A3: Parametro | B3: Valor | C3: Sustento / fuente
A4: Horas efectivas por persona por dia | B4: 4 | C4: Dedicacion parcial: equipo de 5 estudiantes con carga academica paralela (restriccion 2.5 del caso)
A5: Tamano del equipo | B5: 5 | C5: Hernando, Jhonatan, Juanita, Laura y Santiago
A6: Salario base mensual ingeniero junior | B6: 2820000 | C6: Promedio de mercado Bogota 2026 (Indeed: $2.827.195; Computrabajo: rango $2.6M-$3.2M)
A7: Factor prestacional | B7: 1.5 | C7: Cesantias, intereses, prima, vacaciones, salud, pension, ARL y parafiscales
A8: Costo empresa mensual | B8: =B6*B7 -> 4230000 | C8: Salario base x factor prestacional
A9: Horas laborales al mes | B9: 190 | C9: Jornada de 44 h/semana (Ley 2101 de 2021, fase vigente desde julio 2026) x 4,33 semanas
A10: TARIFA HORA-PERSONA | B10: =B8/B9 -> 22263.158 | C10: Costo empresa mensual / horas laborales al mes
A11: Costo de infraestructura | B11: 0 | C11: Restriccion del proyecto: despliegue en servicios gratuitos o ambiente local
A13: Celdas en azul = supuestos editables. Celdas en negro = calculadas por formula.
A14: Cambiar un supuesto recalcula automaticamente todo el cronograma y el resumen por EDT.

Sheet Cronograma
A1: ID EDT | B1: Paquete EDT | C1: Actividad | D1: Responsable | E1: Duracion (dias habiles) | F1: Predecesoras | G1: Inicio | H1: Fin | I1: Hito | J1: Ruta critica | K1: Solape / nota | L1: Entrega del curso asociada | M1: Paquete EDT N2 | N1: Personas asignadas | O1: Horas-persona | P1: Costo de la actividad
A2: 2.1.1 | B2: 2.1 | C2: Levantamiento de requisitos, normativa y restricciones | D2: Equipo completo | E2: 4 | F2: - | G2: 14/08/2026 | H2: 19/08/2026 | I2: No | J2: Si | K2: Ya completado antes del inicio de este cronograma (antes del 02-sep-2026) | M2: 2 | N2: =IF($D2="Equipo completo",Supuestos!$B$5,1) -> 5 | O2: =IF(ISNUMBER($E2),$E2*$N2*Supuestos!$B$4,0) -> 80 | P2: =$O2*Supuestos!$B$10 -> 1781052.6
A3: 2.2.1 | B3: 2.2 | C3: Especificar requisitos funcionales y no funcionales (RF/RNF) | D3: Equipo completo | E3: 5 | F3: 2.1.1 | G3: 20/08/2026 | H3: 26/08/2026 | I3: No | J3: Si | K3: Ya completado antes del inicio de este cronograma (antes del 02-sep-2026) | M3: 2 | N3: =IF($D3="Equipo completo",Supuestos!$B$5,1) -> 5 | O3: =IF(ISNUMBER($E3),$E3*$N3*Supuestos!$B$4,0) -> 100 | P3: =$O3*Supuestos!$B$10 -> 2226315.8
A4: 1.1.1 | B4: 1.1 | C4: Finalizar EDT y plan de trabajo | D4: Equipo completo | E4: 3 | F4: - | G4: 02/09/2026 | H4: 04/09/2026 | I4: No | J4: Si | M4: 1 | N4: =IF($D4="Equipo completo",Supuestos!$B$5,1) -> 5 | O4: =IF(ISNUMBER($E4),$E4*$N4*Supuestos!$B$4,0) -> 60 | P4: =$O4*Supuestos!$B$10 -> 1335789.5
A5: 2.3.1 | B5: 2.3 | C5: Ajustar RF/RNF y validar criterios de aceptacion con el profesor | D5: Laura | E5: 3 | F5: 2.2.1 | G5: 02/09/2026 | H5: 04/09/2026 | I5: No | J5: Si | M5: 2 | N5: =IF($D5="Equipo completo",Supuestos!$B$5,1) -> 1 | O5: =IF(ISNUMBER($E5),$E5*$N5*Supuestos!$B$4,0) -> 12 | P5: =$O5*Supuestos!$B$10 -> 267157.89
A6: 1.1.2 | B6: 1.1 | C6: Elaborar cronograma y diagrama de Gantt | D6: Juanita | E6: 3 | F6: 1.1.1; 2.3.1 | G6: 07/09/2026 | H6: 09/09/2026 | I6: No | J6: Si | M6: 1 | N6: =IF($D6="Equipo completo",Supuestos!$B$5,1) -> 1 | O6: =IF(ISNUMBER($E6),$E6*$N6*Supuestos!$B$4,0) -> 12 | P6: =$O6*Supuestos!$B$10 -> 267157.89
A7: 1.3.1 | B7: 1.3 | C7: Preparar y sustentar entrega semana 5 | D7: Equipo completo | E7: 3 | F7: 1.1.2 | G7: 09/09/2026 | H7: 11/09/2026 | I7: No | J7: Si | K7: Inicio-inicio con el ultimo dia de 1.1.2 (solape de 1 dia) para no perder tiempo antes de la entrega del 11-sep | M7: 1 | N7: =IF($D7="Equipo completo",Supuestos!$B$5,1) -> 5 | O7: =IF(ISNUMBER($E7),$E7*$N7*Supuestos!$B$4,0) -> 60 | P7: =$O7*Supuestos!$B$10 -> 1335789.5
A8: H1 | B8: Hito | C8: H1 Requisitos aprobados por el cliente | D8: Equipo completo | E8: - | F8: 1.3.1 | G8: 11/09/2026 | H8: 11/09/2026 | I8: Si | J8: Si | L8: Entrega curso: objetivos/alcance/EDT/requisitos/cronograma (10%) | M8: Hito | N8: - | O8: 0 | P8: =$O8*Supuestos!$B$10 -> 0
A9: 3.1.1 | B9: 3.1 | C9: Arquitectura de software y decisiones de diseno | D9: Santiago | E9: 4 | F9: H1 | G9: 14/09/2026 | H9: 17/09/2026 | I9: No | J9: No | M9: 3 | N9: =IF($D9="Equipo completo",Supuestos!$B$5,1) -> 1 | O9: =IF(ISNUMBER($E9),$E9*$N9*Supuestos!$B$4,0) -> 16 | P9: =$O9*Supuestos!$B$10 -> 356210.53
A10: 3.2.1 | B10: 3.2 | C10: Modelo de datos conceptual, logico y fisico (3FN) | D10: Juanita | E10: 6 | F10: H1 | G10: 14/09/2026 | H10: 21/09/2026 | I10: No | J10: Si | M10: 3 | N10: =IF($D10="Equipo completo",Supuestos!$B$5,1) -> 1 | O10: =IF(ISNUMBER($E10),$E10*$N10*Supuestos!$B$4,0) -> 24 | P10: =$O10*Supuestos!$B$10 -> 534315.79
A11: 3.3.1 | B11: 3.3 | C11: Diseno de interfaz (wireframes, tablero drag-and-drop) | D11: Laura | E11: 3 | F11: 3.1.1 | G11: 18/09/2026 | H11: 22/09/2026 | I11: No | J11: No | M11: 3 | N11: =IF($D11="Equipo completo",Supuestos!$B$5,1) -> 1 | O11: =IF(ISNUMBER($E11),$E11*$N11*Supuestos!$B$4,0) -> 12 | P11: =$O11*Supuestos!$B$10 -> 267157.89
A12: 3.4.1 | B12: 3.4 | C12: Diseno del motor de reglas y del algoritmo voraz | D12: Santiago | E12: 4 | F12: 3.1.1 | G12: 18/09/2026 | H12: 23/09/2026 | I12: No | J12: No | M12: 3 | N12: =IF($D12="Equipo completo",Supuestos!$B$5,1) -> 1 | O12: =IF(ISNUMBER($E12),$E12*$N12*Supuestos!$B$4,0) -> 16 | P12: =$O12*Supuestos!$B$10 -> 356210.53
A13: H2 | B13: Hito | C13: H2 Modelo de datos aprobado | D13: Equipo completo | E13: - | F13: 3.2.1 | G13: 22/09/2026 | H13: 22/09/2026 | I13: Si | J13: Si | M13: Hito | N13: - | O13: 0 | P13: =$O13*Supuestos!$B$10 -> 0
A14: 1.3.2 | B14: 1.3 | C14: Preparar presentacion de fase de diseno | D14: Hernando | E14: 3 | F14: 3.3.1; 3.4.1 | G14: 23/09/2026 | H14: 25/09/2026 | I14: No | J14: No | K14: Inicio-inicio con el ultimo dia de 3.3.1 y 3.4.1 (solape de 1 dia, usa el material ya avanzado esa misma tarde) | L14: Entrega curso: fase de diseno (10%) | M14: 1 | N14: =IF($D14="Equipo completo",Supuestos!$B$5,1) -> 1 | O14: =IF(ISNUMBER($E14),$E14*$N14*Supuestos!$B$4,0) -> 12 | P14: =$O14*Supuestos!$B$10 -> 267157.89
A15: 1.1.3 | B15: 1.1 | C15: Elaborar backlog priorizado | D15: Hernando | E15: 4 | F15: H1 | G15: 28/09/2026 | H15: 01/10/2026 | I15: No | J15: No | M15: 1 | N15: =IF($D15="Equipo completo",Supuestos!$B$5,1) -> 1 | O15: =IF(ISNUMBER($E15),$E15*$N15*Supuestos!$B$4,0) -> 16 | P15: =$O15*Supuestos!$B$10 -> 356210.53
A16: 1.1.4 | B16: 1.1 | C16: Estimar costos del proyecto (horas x persona, recursos) | D16: Jhonatan | E16: 4 | F16: H1 | G16: 28/09/2026 | H16: 01/10/2026 | I16: No | J16: Si | M16: 1 | N16: =IF($D16="Equipo completo",Supuestos!$B$5,1) -> 1 | O16: =IF(ISNUMBER($E16),$E16*$N16*Supuestos!$B$4,0) -> 16 | P16: =$O16*Supuestos!$B$10 -> 356210.53
A17: 4.1.1 | B17: 4.1 | C17: BD fisica y datos semilla | D17: Juanita | E17: 4 | F17: H2 | G17: 28/09/2026 | H17: 01/10/2026 | I17: No | J17: Si | M17: 4 | N17: =IF($D17="Equipo completo",Supuestos!$B$5,1) -> 1 | O17: =IF(ISNUMBER($E17),$E17*$N17*Supuestos!$B$4,0) -> 16 | P17: =$O17*Supuestos!$B$10 -> 356210.53
A18: 1.3.3 | B18: 1.3 | C18: Preparar presentacion de backlog y costo | D18: Laura | E18: 3 | F18: 1.1.3; 1.1.4 | G18: 02/10/2026 | H18: 06/10/2026 | I18: No | J18: No | L18: Entrega curso: backlog y costo (10%) | M18: 1 | N18: =IF($D18="Equipo completo",Supuestos!$B$5,1) -> 1 | O18: =IF(ISNUMBER($E18),$E18*$N18*Supuestos!$B$4,0) -> 12 | P18: =$O18*Supuestos!$B$10 -> 267157.89
A19: 4.2.1 | B19: 4.2 | C19: Backend: CRUD del dominio (parte 1) | D19: Jhonatan | E19: 8 | F19: 4.1.1; 1.1.4 | G19: 02/10/2026 | H19: 13/10/2026 | I19: No | J19: Si | M19: 4 | N19: =IF($D19="Equipo completo",Supuestos!$B$5,1) -> 1 | O19: =IF(ISNUMBER($E19),$E19*$N19*Supuestos!$B$4,0) -> 32 | P19: =$O19*Supuestos!$B$10 -> 712421.05
A20: 4.4.1 | B20: 4.4 | C20: Generador de propuesta inicial (algoritmo voraz) | D20: Hernando | E20: 7 | F20: 3.4.1 | G20: 02/10/2026 | H20: 12/10/2026 | I20: No | J20: No | K20: Avanza contra la interfaz de validacion como stub (RNF-04), en paralelo con 4.3.1; se integra con el motor real antes de H4 | M20: 4 | N20: =IF($D20="Equipo completo",Supuestos!$B$5,1) -> 1 | O20: =IF(ISNUMBER($E20),$E20*$N20*Supuestos!$B$4,0) -> 28 | P20: =$O20*Supuestos!$B$10 -> 623368.42
A21: 6.1.1 | B21: 6.1 | C21: Configurar infraestructura y pipeline CI/CD | D21: Santiago | E21: 5 | F21: 4.1.1 | G21: 02/10/2026 | H21: 08/10/2026 | I21: No | J21: No | M21: 6 | N21: =IF($D21="Equipo completo",Supuestos!$B$5,1) -> 1 | O21: =IF(ISNUMBER($E21),$E21*$N21*Supuestos!$B$4,0) -> 20 | P21: =$O21*Supuestos!$B$10 -> 445263.16
A22: 4.5.1 | B22: 4.5 | C22: Frontend: tablero semanal drag-and-drop | D22: Laura | E22: 8 | F22: 4.2.1 | G22: 08/10/2026 | H22: 19/10/2026 | I22: No | J22: Si | K22: Inicio-inicio con 4.2.1: avanza con datos simulados antes de que el generador este terminado | M22: 4 | N22: =IF($D22="Equipo completo",Supuestos!$B$5,1) -> 1 | O22: =IF(ISNUMBER($E22),$E22*$N22*Supuestos!$B$4,0) -> 32 | P22: =$O22*Supuestos!$B$10 -> 712421.05
A23: 4.3.1 | B23: 4.3 | C23: Motor de validacion de restricciones duras | D23: Santiago | E23: 4 | F23: 3.4.1; 4.2.1 | G23: 14/10/2026 | H23: 19/10/2026 | I23: No | J23: Si | M23: 4 | N23: =IF($D23="Equipo completo",Supuestos!$B$5,1) -> 1 | O23: =IF(ISNUMBER($E23),$E23*$N23*Supuestos!$B$4,0) -> 16 | P23: =$O23*Supuestos!$B$10 -> 356210.53
A24: 4.6.1 | B24: 4.6 | C24: Reportes, indicadores y exportacion (CSV/PDF) | D24: Jhonatan | E24: 3 | F24: 4.2.1 | G24: 14/10/2026 | H24: 16/10/2026 | I24: No | J24: No | M24: 4 | N24: =IF($D24="Equipo completo",Supuestos!$B$5,1) -> 1 | O24: =IF(ISNUMBER($E24),$E24*$N24*Supuestos!$B$4,0) -> 12 | P24: =$O24*Supuestos!$B$10 -> 267157.89
A25: H3 | B25: Hito | C25: H3 Motor de reglas funcionando y probado | D25: Equipo completo | E25: - | F25: 4.3.1 | G25: 19/10/2026 | H25: 19/10/2026 | I25: Si | J25: Si | M25: Hito | N25: - | O25: 0 | P25: =$O25*Supuestos!$B$10 -> 0
A26: 1.3.4 | B26: 1.3 | C26: Integrar y preparar sustentacion del prototipo (CI/CD) | D26: Equipo completo | E26: 3 | F26: 4.4.1; 4.5.1; 4.6.1; 6.1.1; H3 | G26: 20/10/2026 | H26: 22/10/2026 | I26: No | J26: Si | L26: Entrega curso: prototipo integrado navegable + CI/CD (20%) | M26: 1 | N26: =IF($D26="Equipo completo",Supuestos!$B$5,1) -> 5 | O26: =IF(ISNUMBER($E26),$E26*$N26*Supuestos!$B$4,0) -> 60 | P26: =$O26*Supuestos!$B$10 -> 1335789.5
A27: H4 | B27: Hito | C27: H4 Prototipo integrado navegable | D27: Equipo completo | E27: - | F27: 1.3.4 | G27: 22/10/2026 | H27: 22/10/2026 | I27: Si | J27: Si | M27: Hito | N27: - | O27: 0 | P27: =$O27*Supuestos!$B$10 -> 0
A28: 5.1.1 | B28: 5.1 | C28: Elaborar plan de pruebas | D28: Jhonatan | E28: 5 | F28: H4 | G28: 26/10/2026 | H28: 30/10/2026 | I28: No | J28: No | M28: 5 | N28: =IF($D28="Equipo completo",Supuestos!$B$5,1) -> 1 | O28: =IF(ISNUMBER($E28),$E28*$N28*Supuestos!$B$4,0) -> 20 | P28: =$O28*Supuestos!$B$10 -> 445263.16
A29: 5.1.2 | B29: 5.1 | C29: Ejecutar pruebas de integracion y de interfaz | D29: Hernando | E29: 5 | F29: H4 | G29: 26/10/2026 | H29: 30/10/2026 | I29: No | J29: Si | M29: 5 | N29: =IF($D29="Equipo completo",Supuestos!$B$5,1) -> 1 | O29: =IF(ISNUMBER($E29),$E29*$N29*Supuestos!$B$4,0) -> 20 | P29: =$O29*Supuestos!$B$10 -> 445263.16
A30: 5.2.1 | B30: 5.2 | C30: Prueba con juego de datos representativo del Programa | D30: Juanita | E30: 3 | F30: 5.1.2 | G30: 02/11/2026 | H30: 04/11/2026 | I30: No | J30: Si | M30: 5 | N30: =IF($D30="Equipo completo",Supuestos!$B$5,1) -> 1 | O30: =IF(ISNUMBER($E30),$E30*$N30*Supuestos!$B$4,0) -> 12 | P30: =$O30*Supuestos!$B$10 -> 267157.89
A31: 1.3.5 | B31: 1.3 | C31: Preparar presentacion de plan de pruebas | D31: Laura | E31: 3 | F31: 5.1.1; 5.2.1 | G31: 04/11/2026 | H31: 06/11/2026 | I31: No | J31: No | K31: Inicio-inicio con el ultimo dia de 5.2.1 (solape de 1 dia) | L31: Entrega curso: plan de pruebas (10%) | M31: 1 | N31: =IF($D31="Equipo completo",Supuestos!$B$5,1) -> 1 | O31: =IF(ISNUMBER($E31),$E31*$N31*Supuestos!$B$4,0) -> 12 | P31: =$O31*Supuestos!$B$10 -> 267157.89
A32: 1.2.1 | B32: 1.2 | C32: Elaborar matriz de riesgos y plan de mitigacion | D32: Juanita | E32: 3 | F32: H1 | G32: 09/11/2026 | H32: 11/11/2026 | I32: No | J32: No | M32: 1 | N32: =IF($D32="Equipo completo",Supuestos!$B$5,1) -> 1 | O32: =IF(ISNUMBER($E32),$E32*$N32*Supuestos!$B$4,0) -> 12 | P32: =$O32*Supuestos!$B$10 -> 267157.89
A33: 5.3.1 | B33: 5.3 | C33: Correccion de defectos | D33: Santiago | E33: 6 | F33: 5.2.1 | G33: 09/11/2026 | H33: 16/11/2026 | I33: No | J33: Si | M33: 5 | N33: =IF($D33="Equipo completo",Supuestos!$B$5,1) -> 1 | O33: =IF(ISNUMBER($E33),$E33*$N33*Supuestos!$B$4,0) -> 24 | P33: =$O33*Supuestos!$B$10 -> 534315.79
A34: 1.3.6 | B34: 1.3 | C34: Preparar presentacion de riesgos | D34: Hernando | E34: 3 | F34: 1.2.1 | G34: 16/11/2026 | H34: 18/11/2026 | I34: No | J34: No | L34: Entrega curso: riesgos (10%) | M34: 1 | N34: =IF($D34="Equipo completo",Supuestos!$B$5,1) -> 1 | O34: =IF(ISNUMBER($E34),$E34*$N34*Supuestos!$B$4,0) -> 12 | P34: =$O34*Supuestos!$B$10 -> 267157.89
A35: 6.1.2 | B35: 6.1 | C35: Despliegue en ambiente de demostracion | D35: Jhonatan | E35: 3 | F35: 5.3.1 | G35: 23/11/2026 | H35: 25/11/2026 | I35: No | J35: Si | M35: 6 | N35: =IF($D35="Equipo completo",Supuestos!$B$5,1) -> 1 | O35: =IF(ISNUMBER($E35),$E35*$N35*Supuestos!$B$4,0) -> 12 | P35: =$O35*Supuestos!$B$10 -> 267157.89
A36: 6.3.1 | B36: 6.3 | C36: Documento final (formato IEEE) y manual de usuario | D36: Juanita | E36: 3 | F36: 5.3.1 | G36: 23/11/2026 | H36: 25/11/2026 | I36: No | J36: Si | M36: 6 | N36: =IF($D36="Equipo completo",Supuestos!$B$5,1) -> 1 | O36: =IF(ISNUMBER($E36),$E36*$N36*Supuestos!$B$4,0) -> 12 | P36: =$O36*Supuestos!$B$10 -> 267157.89
A37: 6.2.1 | B37: 6.2 | C37: Capacitacion, ensayo y sustentacion final | D37: Laura | E37: 3 | F37: 6.1.2; 6.3.1 | G37: 25/11/2026 | H37: 27/11/2026 | I37: No | J37: Si | K37: Inicio-inicio con el ultimo dia de 6.1.2 y 6.3.1 (solape de 1 dia) para llegar a tiempo a H5 | M37: 6 | N37: =IF($D37="Equipo completo",Supuestos!$B$5,1) -> 1 | O37: =IF(ISNUMBER($E37),$E37*$N37*Supuestos!$B$4,0) -> 12 | P37: =$O37*Supuestos!$B$10 -> 267157.89
A38: H5 | B38: Hito | C38: H5 Entrega y sustentacion final | D38: Equipo completo | E38: - | F38: 6.2.1 | G38: 27/11/2026 | H38: 27/11/2026 | I38: Si | J38: Si | L38: Cierre de notas del curso (100%) | M38: Hito | N38: - | O38: 0 | P38: =$O38*Supuestos!$B$10 -> 0
L39: TOTAL PROYECTO | O39: =SUM(O2:O38) -> 812 | P39: =SUM(P2:P38) -> 18077684

Sheet Costos_EDT
A1: Costos agrupados por EDT de segundo nivel
A3: EDT | B3: Paquete de trabajo | C3: Dias-actividad | D3: Horas-persona | E3: Costo | F3: % del total
A4: 1 | B4: Gestion del Proyecto | C4: =SUMIFS(Cronograma!$E$2:$E$38,Cronograma!$M$2:$M$38,$A4) -> 35 | D4: =SUMIFS(Cronograma!$O$2:$O$38,Cronograma!$M$2:$M$38,$A4) -> 284 | E4: =SUMIFS(Cronograma!$P$2:$P$38,Cronograma!$M$2:$M$38,$A4) -> 6322736.8 | F4: =IFERROR($E4/$E$10,0) -> 0.34975369
A5: 2 | B5: Ingenieria de Requisitos | C5: =SUMIFS(Cronograma!$E$2:$E$38,Cronograma!$M$2:$M$38,$A5) -> 12 | D5: =SUMIFS(Cronograma!$O$2:$O$38,Cronograma!$M$2:$M$38,$A5) -> 192 | E5: =SUMIFS(Cronograma!$P$2:$P$38,Cronograma!$M$2:$M$38,$A5) -> 4274526.3 | F5: =IFERROR($E5/$E$10,0) -> 0.2364532
A6: 3 | B6: Diseno | C6: =SUMIFS(Cronograma!$E$2:$E$38,Cronograma!$M$2:$M$38,$A6) -> 17 | D6: =SUMIFS(Cronograma!$O$2:$O$38,Cronograma!$M$2:$M$38,$A6) -> 68 | E6: =SUMIFS(Cronograma!$P$2:$P$38,Cronograma!$M$2:$M$38,$A6) -> 1513894.7 | F6: =IFERROR($E6/$E$10,0) -> 0.083743842
A7: 4 | B7: Construccion | C7: =SUMIFS(Cronograma!$E$2:$E$38,Cronograma!$M$2:$M$38,$A7) -> 34 | D7: =SUMIFS(Cronograma!$O$2:$O$38,Cronograma!$M$2:$M$38,$A7) -> 136 | E7: =SUMIFS(Cronograma!$P$2:$P$38,Cronograma!$M$2:$M$38,$A7) -> 3027789.5 | F7: =IFERROR($E7/$E$10,0) -> 0.16748768
A8: 5 | B8: Pruebas y Verificacion | C8: =SUMIFS(Cronograma!$E$2:$E$38,Cronograma!$M$2:$M$38,$A8) -> 19 | D8: =SUMIFS(Cronograma!$O$2:$O$38,Cronograma!$M$2:$M$38,$A8) -> 76 | E8: =SUMIFS(Cronograma!$P$2:$P$38,Cronograma!$M$2:$M$38,$A8) -> 1692000 | F8: =IFERROR($E8/$E$10,0) -> 0.093596059
A9: 6 | B9: Cierre y Despliegue | C9: =SUMIFS(Cronograma!$E$2:$E$38,Cronograma!$M$2:$M$38,$A9) -> 14 | D9: =SUMIFS(Cronograma!$O$2:$O$38,Cronograma!$M$2:$M$38,$A9) -> 56 | E9: =SUMIFS(Cronograma!$P$2:$P$38,Cronograma!$M$2:$M$38,$A9) -> 1246736.8 | F9: =IFERROR($E9/$E$10,0) -> 0.068965517
B10: COSTO NETO TOTAL DEL PROYECTO | C10: =SUM(C4:C9) -> 131 | D10: =SUM(D4:D9) -> 812 | E10: =SUM(E4:E9) -> 18077684 | F10: 1
A12: Costo por recurso (persona)
A14: Responsable | B14: Dias-actividad | C14: Horas-persona | D14: Costo
A15: Juanita | B15: =SUMIFS(Cronograma!$E$2:$E$38,Cronograma!$D$2:$D$38,$A15) -> 22 | C15: =SUMIFS(Cronograma!$O$2:$O$38,Cronograma!$D$2:$D$38,$A15) -> 88 | D15: =SUMIFS(Cronograma!$P$2:$P$38,Cronograma!$D$2:$D$38,$A15) -> 1959157.9
A16: Hernando | B16: =SUMIFS(Cronograma!$E$2:$E$38,Cronograma!$D$2:$D$38,$A16) -> 22 | C16: =SUMIFS(Cronograma!$O$2:$O$38,Cronograma!$D$2:$D$38,$A16) -> 88 | D16: =SUMIFS(Cronograma!$P$2:$P$38,Cronograma!$D$2:$D$38,$A16) -> 1959157.9
A17: Jhonatan | B17: =SUMIFS(Cronograma!$E$2:$E$38,Cronograma!$D$2:$D$38,$A17) -> 23 | C17: =SUMIFS(Cronograma!$O$2:$O$38,Cronograma!$D$2:$D$38,$A17) -> 92 | D17: =SUMIFS(Cronograma!$P$2:$P$38,Cronograma!$D$2:$D$38,$A17) -> 2048210.5
A18: Laura | B18: =SUMIFS(Cronograma!$E$2:$E$38,Cronograma!$D$2:$D$38,$A18) -> 23 | C18: =SUMIFS(Cronograma!$O$2:$O$38,Cronograma!$D$2:$D$38,$A18) -> 92 | D18: =SUMIFS(Cronograma!$P$2:$P$38,Cronograma!$D$2:$D$38,$A18) -> 2048210.5
A19: Santiago | B19: =SUMIFS(Cronograma!$E$2:$E$38,Cronograma!$D$2:$D$38,$A19) -> 23 | C19: =SUMIFS(Cronograma!$O$2:$O$38,Cronograma!$D$2:$D$38,$A19) -> 92 | D19: =SUMIFS(Cronograma!$P$2:$P$38,Cronograma!$D$2:$D$38,$A19) -> 2048210.5
A20: Equipo completo | B20: =SUMIFS(Cronograma!$E$2:$E$38,Cronograma!$D$2:$D$38,$A20) -> 18 | C20: =SUMIFS(Cronograma!$O$2:$O$38,Cronograma!$D$2:$D$38,$A20) -> 360 | D20: =SUMIFS(Cronograma!$P$2:$P$38,Cronograma!$D$2:$D$38,$A20) -> 8014736.8
A21: TOTAL | B21: =SUM(B15:B20) -> 131 | C21: =SUM(C15:C20) -> 812 | D21: =SUM(D15:D20) -> 18077684
A23: Nota: "Equipo completo" agrupa las actividades en que participan los cinco integrantes
A24: (levantamiento, especificacion, EDT, sustentaciones e integracion del prototipo), costeadas a 5 personas.
A25: Los hitos H1-H5 no consumen recursos: son puntos de control, no actividades.

Sheet Estimacion_PERT
A1: ID EDT | B1: Actividad | C1: Optimista (O) | D1: Mas probable (M) | E1: Pesimista (P) | F1: Duracion esperada = (O+4M+P)/6 | G1: Duracion usada
A2: 2.1.1 | B2: Levantamiento de requisitos, normativa y restricciones | C2: 3 | D2: 4 | E2: 5 | F2: =(C2+4*D2+E2)/6 -> 4 | G2: 4
A3: 2.2.1 | B3: Especificar requisitos funcionales y no funcionales (RF/RNF) | C3: 4 | D3: 5 | E3: 6 | F3: =(C3+4*D3+E3)/6 -> 5 | G3: 5
A4: 1.1.1 | B4: Finalizar EDT y plan de trabajo | C4: 2 | D4: 3 | E4: 4 | F4: =(C4+4*D4+E4)/6 -> 3 | G4: 3
A5: 2.3.1 | B5: Ajustar RF/RNF y validar criterios de aceptacion con el profesor | C5: 2 | D5: 3 | E5: 4 | F5: =(C5+4*D5+E5)/6 -> 3 | G5: 3
A6: 1.1.2 | B6: Elaborar cronograma y diagrama de Gantt | C6: 2 | D6: 3 | E6: 4 | F6: =(C6+4*D6+E6)/6 -> 3 | G6: 3
A7: 1.3.1 | B7: Preparar y sustentar entrega semana 5 | C7: 2 | D7: 3 | E7: 4 | F7: =(C7+4*D7+E7)/6 -> 3 | G7: 3
A8: 3.1.1 | B8: Arquitectura de software y decisiones de diseno | C8: 3 | D8: 4 | E8: 5 | F8: =(C8+4*D8+E8)/6 -> 4 | G8: 4
A9: 3.2.1 | B9: Modelo de datos conceptual, logico y fisico (3FN) | C9: 5 | D9: 6 | E9: 7 | F9: =(C9+4*D9+E9)/6 -> 6 | G9: 6
A10: 3.3.1 | B10: Diseno de interfaz (wireframes, tablero drag-and-drop) | C10: 2 | D10: 3 | E10: 4 | F10: =(C10+4*D10+E10)/6 -> 3 | G10: 3
A11: 3.4.1 | B11: Diseno del motor de reglas y del algoritmo voraz | C11: 3 | D11: 4 | E11: 5 | F11: =(C11+4*D11+E11)/6 -> 4 | G11: 4
A12: 1.3.2 | B12: Preparar presentacion de fase de diseno | C12: 2 | D12: 3 | E12: 4 | F12: =(C12+4*D12+E12)/6 -> 3 | G12: 3
A13: 1.1.3 | B13: Elaborar backlog priorizado | C13: 3 | D13: 4 | E13: 5 | F13: =(C13+4*D13+E13)/6 -> 4 | G13: 4
... A33: 6.2.1 | B33: Capacitacion, ensayo y sustentacion final | C33: 2 | D33: 3 | E33: 4 | F33: =(C33+4*D33+E33)/6 -> 3 | G33: 3

Sheet Gantt
A1: ID EDT | B1: Actividad / Responsable | C1: Aug | O1: Sep | AK1: Oct | BG1: Nov
C2: 14 | D2: 17 | E2: 18 | F2: 19 | G2: 20 | H2: 21 | I2: 24 | J2: 25 | K2: 26 | L2: 27 | M2: 28 | N2: 31 | O2: 01 | P2: 02 | Q2: 03 | R2: 04 | S2: 07 | T2: 08 | U2: 09 | V2: 10 | W2: 11 | X2: 14 | Y2: 15 | Z2: 16 | AA2: 17 | AB2: 18 | AC2: 21 | AD2: 22 | AE2: 23 | AF2: 24 | AG2: 25 | AH2: 28 | AI2: 29 | AJ2: 30 | AK2: 01 | AL2: 02 | AM2: 05 | AN2: 06 | AO2: 07 | AP2: 08 | AQ2: 09 | AR2: 12 | AS2: 13 | AT2: 14 | AU2: 15 | AV2: 16 | AW2: 19 | AX2: 20 | AY2: 21 | AZ2: 22 | BA2: 23 | BB2: 26 | BC2: 27 | BD2: 28 | BE2: 29 | BF2: 30 | BG2: 02 | BH2: 03 | BI2: 04 | BJ2: 05 | BK2: 06 | BL2: 09 | BM2: 10 | BN2: 11 | BO2: 12 | BP2: 13 | BQ2: 16 | BR2: 17 | BS2: 18 | BT2: 19 | BU2: 20 | BV2: 23 | BW2: 24 | BX2: 25 | BY2: 26 | BZ2: 27
A3: 2.1.1 | B3: Levantamiento de requisitos, normativa y restricciones (Equipo completo)
A4: 2.2.1 | B4: Especificar requisitos funcionales y no funcionales (RF/RNF) (Equipo completo)
A5: 1.1.1 | B5: Finalizar EDT y plan de trabajo (Equipo completo)
A6: 2.3.1 | B6: Ajustar RF/RNF y validar criterios de aceptacion con el profesor (Laura)
A7: 1.1.2 | B7: Elaborar cronograma y diagrama de Gantt (Juanita)
A8: 1.3.1 | B8: Preparar y sustentar entrega semana 5 (Equipo completo)
A9: H1 | B9: H1 Requisitos aprobados por el cliente (Equipo completo) | W9: H
A10: 3.1.1 | B10: Arquitectura de software y decisiones de diseno (Santiago)
A11: 3.2.1 | B11: Modelo de datos conceptual, logico y fisico (3FN) (Juanita)
A12: 3.3.1 | B12: Diseno de interfaz (wireframes, tablero drag-and-drop) (Laura)
A13: 3.4.1 | B13: Diseno del motor de reglas y del algoritmo voraz (Santiago)
A14: H2 | B14: H2 Modelo de datos aprobado (Equipo completo) | AD14: H
A15: 1.3.2 | B15: Preparar presentacion de fase de diseno (Hernando)
A16: 1.1.3 | B16: Elaborar backlog priorizado (Hernando)
A17: 1.1.4 | B17: Estimar costos del proyecto (horas x persona, recursos) (Jhonatan)
A18: 4.1.1 | B18: BD fisica y datos semilla (Juanita)
A19: 1.3.3 | B19: Preparar presentacion de backlog y costo (Laura)
A20: 4.2.1 | B20: Backend: CRUD del dominio (parte 1) (Jhonatan)
A21: 4.4.1 | B21: Generador de propuesta inicial (algoritmo voraz) (Hernando)
A22: 6.1.1 | B22: Configurar infraestructura y pipeline CI/CD (Santiago)
A23: 4.5.1 | B23: Frontend: tablero semanal drag-and-drop (Laura)
A24: 4.3.1 | B24: Motor de validacion de restricciones duras (Santiago)
A25: 4.6.1 | B25: Reportes, indicadores y exportacion (CSV/PDF) (Jhonatan)
A26: H3 | B26: H3 Motor de reglas funcionando y probado (Equipo completo) | AW26: H
A27: 1.3.4 | B27: Integrar y preparar sustentacion del prototipo (CI/CD) (Equipo completo)
A28: H4 | B28: H4 Prototipo integrado navegable (Equipo completo) | AZ28: H
A29: 5.1.1 | B29: Elaborar plan de pruebas (Jhonatan)
A30: 5.1.2 | B30: Ejecutar pruebas de integracion y de interfaz (Hernando)
A31: 5.2.1 | B31: Prueba con juego de datos representativo del Programa (Juanita)
A32: 1.3.5 | B32: Preparar presentacion de plan de pruebas (Laura)
A33: 1.2.1 | B33: Elaborar matriz de riesgos y plan de mitigacion (Juanita)
A34: 5.3.1 | B34: Correccion de defectos (Santiago)
A35: 1.3.6 | B35: Preparar presentacion de riesgos (Hernando)
A36: 6.1.2 | B36: Despliegue en ambiente de demostracion (Jhonatan)
A37: 6.3.1 | B37: Documento final (formato IEEE) y manual de usuario (Juanita)
A38: 6.2.1 | B38: Capacitacion, ensayo y sustentacion final (Laura)
A39: H5 | B39: H5 Entrega y sustentacion final (Equipo completo) | BZ39: H
A41: Leyenda:
...
